Workbook

Sheet Resumen
A1: Informe de morosidad – Colegio de Profesionales en Sociología
A2: Moneda: colones. Los indicadores se calculan con fórmulas desde las demás hojas. Corte del padrón: 2-sep-2026.
A4: Indicador | B4: Valor | C4: Detalle
A5: Personas morosas (únicas) | B5: =Tramos!$B$11 -> 427 | C5: Base de morosidad tras eliminar duplicados
A6: Deuda acumulada (₡) | B6: =Tramos!$D$11 -> 1.3111925e+08 | C6: Suma de la deuda de todas las personas morosas
A7: Colegiados en el padrón | B7: =Factores!C24 -> 914 | C7: Todas las condiciones
A8: Tasa de morosidad | B8: =Factores!E24 -> 0.46280088 | C8: Morosos con datos cruzados / colegiados del padrón
A9: Deuda mediana por persona (₡) | B9: =Perfil!$B$61 -> 263750 | C9: Mitad de los morosos debe menos que esto
A10: Atraso mediano (meses) | B10: =Perfil!$B$60 -> 45 | C10: Equivale a unos 3,8 años
A11: Tasa de morosidad: inactivos | B11: =Factores!E7 -> 0.9280397 | C11: Factor principal
A12: Tasa de morosidad: activos | B12: =Factores!E6 -> 0.07249467 | C12: La condición puede ser consecuencia de la mora
A13: Deuda en tramo 97+ meses | B13: =Tramos!E10 -> 0.34861586 | C13: % de la deuda total que llevan más de 8 años en atraso
A14: Deuda recuperable (prioridad A) | B14: =Cobro!D5 -> 0.013949134 | C14: % de la deuda de personas activas o con arreglo y atraso hasta 24 meses
A16: Hallazgos principales
A17: 1. La morosidad se concentra en personas inactivas: 93% de los inactivos frente a 7% de los activos (hoja Factores).
A18: 2. La cohorte incorporada en 2018-2021 tiene la tasa más alta (61%); la de 2022-2026, la más baja (28%).
A19: 3. Edad y sexo explican poco; tener licenciatura se asocia con menos morosidad que el bachillerato (hoja Modelos).
A20: 4. El 17% de los morosos, con más de 8 años de atraso, acumula el 35% de la deuda (hoja Tramos).
A21: 5. Solo 1,4% de la deuda corresponde a personas activas o con arreglo y hasta 24 meses de atraso (hoja Cobro).
A23: Limitaciones: asociaciones, no causas. Sexo e institución no están en el padrón. Ver hoja Calidad.
A24: Leyenda: texto azul = dato de entrada tomado de los scripts de análisis; texto negro = fórmula.

Sheet Tramos
A1: Cartera por tramos de atraso
A2: Moneda: colones (₡). Texto azul = dato de entrada; negro = fórmula. Fuente: Base_Morosidad_completada.xlsx (427 morosos únicos).
A4: Tramo de atraso | B4: Personas | C4: % de personas | D4: Deuda (₡) | E4: % de la deuda
A5: 0-12 meses | B5: 73 | C5: =B5/B$11 -> 0.17096019 | D5: 4091000 | E5: =D5/D$11 -> 0.031200606
A6: 13-24 meses | B6: 69 | C6: =B6/B$11 -> 0.16159251 | D6: 7573000 | E6: =D6/D$11 -> 0.057756584
A7: 25-48 meses | B7: 83 | C7: =B7/B$11 -> 0.19437939 | D7: 17785750 | E7: =D7/D$11 -> 0.13564561
A8: 49-72 meses | B8: 64 | C8: =B8/B$11 -> 0.1498829 | D8: 23308500 | E8: =D8/D$11 -> 0.17776566
A9: 73-96 meses | B9: 66 | C9: =B9/B$11 -> 0.15456674 | D9: 32650750 | E9: =D9/D$11 -> 0.24901569
A10: 97+ meses | B10: 72 | C10: =B10/B$11 -> 0.16861827 | D10: 45710250 | E10: =D10/D$11 -> 0.34861586
A11: Total | B11: =SUM(B5:B10) -> 427 | C11: =SUM(C5:C10) -> 1 | D11: =SUM(D5:D10) -> 1.3111925e+08 | E11: =SUM(E5:E10) -> 1
A13: Nota: el atraso se registra en meses (mínimo 4). En los tramos de 30, 60 y 90 días, el 100% de la cartera cae en 90+ días, por eso se usan tramos en meses.

Sheet Perfil
A1: Perfil de las personas morosas
A2: n = 427 morosos únicos. Texto azul = dato de entrada; negro = fórmula. Fuente: Base_Morosidad_completada.xlsx.
A4: Sexo
A5: Sexo | B5: Personas | C5: % del total
A6: Mujer | B6: 280 | C6: =B6/B$8 -> 0.6557377
A7: Hombre | B7: 147 | C7: =B7/B$8 -> 0.3442623
A8: Total | B8: =SUM(B6:B7) -> 427 | C8: =SUM(C6:C7) -> 1
A11: Grupo de edad
A12: Grupo de edad | B12: Personas | C12: % del total
A13: <35 | B13: 103 | C13: =B13/B$18 -> 0.2412178
A14: 35-44 | B14: 144 | C14: =B14/B$18 -> 0.33723653
A15: 45-54 | B15: 70 | C15: =B15/B$18 -> 0.16393443
A16: 55-64 | B16: 44 | C16: =B16/B$18 -> 0.1030445
A17: 65+ | B17: 66 | C17: =B17/B$18 -> 0.15456674
A18: Total | B18: =SUM(B13:B17) -> 427 | C18: =SUM(C13:C17) -> 1
A21: Institución
A22: Institución | B22: Personas | C22: % del total
A23: Institución Pública | B23: 176 | C23: =B23/B$27 -> 0.41217799
A24: No labora | B24: 144 | C24: =B24/B$27 -> 0.33723653
A25: Institución Privada | B25: 85 | C25: =B25/B$27 -> 0.19906323
A26: Consultoría/propio | B26: 22 | C26: =B26/B$27 -> 0.051522248
A27: Total | B27: =SUM(B23:B26) -> 427 | C27: =SUM(C23:C26) -> 1
A30: Condición
A31: Condición | B31: Personas | C31: % del total
A32: Inactivo | B32: 374 | C32: =B32/B$37 -> 0.87587822
A33: Activo | B33: 34 | C33: =B33/B$37 -> 0.079625293
A34: Arreglo de pago | B34: 14 | C34: =B34/B$37 -> 0.032786885
A35: Artículo 7 (65+ años) | B35: 1 | C35: =B35/B$37 -> 0.0023419204
A36: Sin dato | B36: 4 | C36: =B36/B$37 -> 0.0093676815
A37: Total | B37: =SUM(B32:B36) -> 427 | C37: =SUM(C32:C36) -> 1
A40: Grado académico
A41: Grado académico | B41: Personas | C41: % del total
A42: Bachillerato | B42: 219 | C42: =B42/B$47 -> 0.51288056
A43: Licenciatura | B43: 169 | C43: =B43/B$47 -> 0.39578454
A44: Maestría | B44: 32 | C44: =B44/B$47 -> 0.074941452
A45: Doctorado | B45: 3 | C45: =B45/B$47 -> 0.0070257611
A46: Sin dato | B46: 4 | C46: =B46/B$47 -> 0.0093676815
A47: Total | B47: =SUM(B42:B46) -> 427 | C47: =SUM(C42:C46) -> 1
A50: Segmentación por institución
A51: Institución | B51: Personas | C51: Deuda total (₡) | D51: Edad mediana | E51: Atraso mediano (meses) | F51: Deuda mediana (₡) | G51: % de la deuda
...

Sheet Factores
A1: Tasa de morosidad por factor (padrón completo vs. morosos)
A2: Colegiados = padrón de 914 personas; morosos = personas del padrón presentes en la base de morosidad (423 con datos cruzados). Azul = dato; negro = fórmula.
A3: Valor z (IC 95%) | B3: 1.96 | C3: Supuesto: intervalo de Wilson al 95%.
A5: Factor | B5: Grupo | C5: Colegiados | D5: Morosos | E5: Tasa de morosidad | F5: IC 95% inferior | G5: IC 95% superior
A6: Condición | B6: Activo | C6: 469 | D6: 34 | E6: =D6/C6 -> 0.07249467 | F6: =(E6+$B$3^2/(2*C6)-$B$3*SQRT(E6*(1-E6)/C6+$B$3^2/(4*C6^2)))/(1+$B$3^2/C6) -> 0.052338543 | G6: =(E6+$B$3^2/(2*C6)+$B$3*SQRT(E6*(1-E6)/C6+$B$3^2/(4*C6^2)))/(1+$B$3^2/C6) -> 0.099597327
A7: Condición | B7: Inactivo | C7: 403 | D7: 374 | E7: =D7/C7 -> 0.9280397 | F7: =(E7+$B$3^2/(2*C7)-$B$3*SQRT(E7*(1-E7)/C7+$B$3^2/(4*C7^2)))/(1+$B$3^2/C7) -> 0.89856322 | G7: =(E7+$B$3^2/(2*C7)+$B$3*SQRT(E7*(1-E7)/C7+$B$3^2/(4*C7^2)))/(1+$B$3^2/C7) -> 0.94943265
A8: Condición | B8: Arreglo de pago | C8: 14 | D8: 14 | E8: =D8/C8 -> 1 | F8: =(E8+$B$3^2/(2*C8)-$B$3*SQRT(E8*(1-E8)/C8+$B$3^2/(4*C8^2)))/(1+$B$3^2/C8) -> 0.78468299 | G8: =(E8+$B$3^2/(2*C8)+$B$3*SQRT(E8*(1-E8)/C8+$B$3^2/(4*C8^2)))/(1+$B$3^2/C8) -> 1
A9: Condición | B9: Artículo 7 (65+ años) | C9: 27 | D9: 1 | E9: =D9/C9 -> 0.037037037 | F9: =(E9+$B$3^2/(2*C9)-$B$3*SQRT(E9*(1-E9)/C9+$B$3^2/(4*C9^2)))/(1+$B$3^2/C9) -> 0.0065679765 | G9: =(E9+$B$3^2/(2*C9)+$B$3*SQRT(E9*(1-E9)/C9+$B$3^2/(4*C9^2)))/(1+$B$3^2/C9) -> 0.18283854
A10: Condición | B10: Miembro Honorario | C10: 1 | D10: 0 | E10: =D10/C10 -> 0 | F10: =(E10+$B$3^2/(2*C10)-$B$3*SQRT(E10*(1-E10)/C10+$B$3^2/(4*C10^2)))/(1+$B$3^2/C10) -> 0 | G10: =(E10+$B$3^2/(2*C10)+$B$3*SQRT(E10*(1-E10)/C10+$B$3^2/(4*C10^2)))/(1+$B$3^2/C10) -> 0.79345671
A11: Incorporación | B11: 2012-2013 | C11: 364 | D11: 151 | E11: =D11/C11 -> 0.41483516 | F11: =(E11+$B$3^2/(2*C11)-$B$3*SQRT(E11*(1-E11)/C11+$B$3^2/(4*C11^2)))/(1+$B$3^2/C11) -> 0.36536638 | G11: =(E11+$B$3^2/(2*C11)+$B$3*SQRT(E11*(1-E11)/C11+$B$3^2/(4*C11^2)))/(1+$B$3^2/C11) -> 0.46608281
A12: Incorporación | B12: 2014-2017 | C12: 215 | D12: 120 | E12: =D12/C12 -> 0.55813953 | F12: =(E12+$B$3^2/(2*C12)-$B$3*SQRT(E12*(1-E12)/C12+$B$3^2/(4*C12^2)))/(1+$B$3^2/C12) -> 0.49131417 | G12: =(E12+$B$3^2/(2*C12)+$B$3*SQRT(E12*(1-E12)/C12+$B$3^2/(4*C12^2)))/(1+$B$3^2/C12) -> 0.6229237
A13: Incorporación | B13: 2018-2021 | C13: 180 | D13: 109 | E13: =D13/C13 -> 0.60555556 | F13: =(E13+$B$3^2/(2*C13)-$B$3*SQRT(E13*(1-E13)/C13+$B$3^2/(4*C13^2)))/(1+$B$3^2/C13) -> 0.53266673 | G13: =(E13+$B$3^2/(2*C13)+$B$3*SQRT(E13*(1-E13)/C13+$B$3^2/(4*C13^2)))/(1+$B$3^2/C13) -> 0.67403295
A14: Incorporación | B14: 2022-2026 | C14: 155 | D14: 43 | E14: =D14/C14 -> 0.27741935 | F14: =(E14+$B$3^2/(2*C14)-$B$3*SQRT(E14*(1-E14)/C14+$B$3^2/(4*C14^2)))/(1+$B$3^2/C14) -> 0.21296646 | G14: =(E14+$B$3^2/(2*C14)+$B$3*SQRT(E14*(1-E14)/C14+$B$3^2/(4*C14^2)))/(1+$B$3^2/C14) -> 0.35263852
A15: Grado | B15: Bachillerato | C15: 436 | D15: 219 | E15: =D15/C15 -> 0.50229358 | F15: =(E15+$B$3^2/(2*C15)-$B$3*SQRT(E15*(1-E15)/C15+$B$3^2/(4*C15^2)))/(1+$B$3^2/C15) -> 0.45554595 | G15: =(E15+$B$3^2/(2*C15)+$B$3*SQRT(E15*(1-E15)/C15+$B$3^2/(4*C15^2)))/(1+$B$3^2/C15) -> 0.54900114
A16: Grado | B16: Licenciatura | C16: 407 | D16: 169 | E16: =D16/C16 -> 0.41523342 | F16: =(E16+$B$3^2/(2*C16)-$B$3*SQRT(E16*(1-E16)/C16+$B$3^2/(4*C16^2)))/(1+$B$3^2/C16) -> 0.36837016 | G16: =(E16+$B$3^2/(2*C16)+$B$3*SQRT(E16*(1-E16)/C16+$B$3^2/(4*C16^2)))/(1+$B$3^2/C16) -> 0.4636819
A17: Grado | B17: Maestría | C17: 60 | D17: 32 | E17: =D17/C17 -> 0.53333333 | F17: =(E17+$B$3^2/(2*C17)-$B$3*SQRT(E17*(1-E17)/C17+$B$3^2/(4*C17^2)))/(1+$B$3^2/C17) -> 0.40893209 | G17: =(E17+$B$3^2/(2*C17)+$B$3*SQRT(E17*(1-E17)/C17+$B$3^2/(4*C17^2)))/(1+$B$3^2/C17) -> 0.65372298
... A23: Edad | B23: 65+ | C23: 116 | D23: 66 | E23: =D23/C23 -> 0.56896552 | F23: =(E23+$B$3^2/(2*C23)-$B$3*SQRT(E23*(1-E23)/C23+$B$3^2/(4*C23^2)))/(1+$B$3^2/C23) -> 0.47806242 | G23: =(E23+$B$3^2/(2*C23)+$B$3*SQRT(E23*(1-E23)/C23+$B$3^2/(4*C23^2)))/(1+$B$3^2/C23) -> 0.65544714
A24: Total padrón | C24: =SUM(C6:C10) -> 914 | D24: =SUM(D6:D10) -> 423 | E24: =D24/C24 -> 0.46280088
A26: Nota: la condición se mide al corte del padrón (2-sep-2026) y puede ser consecuencia de la morosidad, no su causa. Miembro Honorario (1 persona) se omite del gráfico.

Sheet Modelos
A1: Modelos de regresión logística (odds ratios)
A2: Odds ratio > 1: más probabilidad de morosidad. Se excluyen las 14 personas con arreglo de pago (todas morosas por definición). Valores calculados en Python (statsmodels).
A4: Modelo sin condición (edad, antigüedad, grado)
A5: Variable | B5: Odds ratio | C5: IC 95% inferior | D5: IC 95% superior | E5: Valor p
A6: grado_g: Licenciatura | B6: 0.5788 | C6: 0.4268 | D6: 0.785 | E6: 0.0004
A7: grado_g: Maestría/Doctorado | B7: 0.7162 | C7: 0.4155 | D7: 1.2344 | E7: 0.2294
A8: edad (+10 años) | B8: 1.1133 | C8: 0.9859 | D8: 1.2572 | E8: 0.0835
A9: antigüedad (+1 año) | B9: 1.0236 | C9: 0.9873 | D9: 1.0613 | E9: 0.2054
A10: Poder de predicción (AUC, validación cruzada) | B10: 0.56
A13: Modelo con condición
A14: Variable | B14: Odds ratio | C14: IC 95% inferior | D14: IC 95% superior | E14: Valor p
A15: grado_g: Licenciatura | B15: 1.2031 | C15: 0.6615 | D15: 2.188 | E15: 0.5446
A16: grado_g: Maestría/Doctorado | B16: 0.9059 | C16: 0.3068 | D16: 2.6751 | E16: 0.858
A17: cond_g: Exento (Art. 7/Honorario) | B17: 0.278 | C17: 0.0341 | D17: 2.268 | E17: 0.232
A18: cond_g: Inactivo | B18: 173.1336 | C18: 101.3819 | D18: 295.6665 | E18: 0
A19: edad (+10 años) | B19: 1.2338 | C19: 0.962 | D19: 1.5824 | E19: 0.0979
A20: antigüedad (+1 año) | B20: 0.9882 | C20: 0.9219 | D20: 1.0594 | E20: 0.7384
A21: Poder de predicción (AUC, validación cruzada) | B21: 0.92
A24: Lectura: sin la condición, las variables disponibles casi no predicen la morosidad (AUC cercano a 0,5). Estar inactivo multiplica el odds por ~173.

Sheet Cobro
A1: Prioridad de cobro (propuesta)
A2: A = colegiado activo o con arreglo y hasta 24 meses de atraso; B = activo/arreglo con más atraso; C = inactivo o sin dato.
A4: Prioridad | B4: Personas | C4: Deuda (₡) | D4: % de la deuda
A5: A - Activo o con arreglo, atraso hasta 24 meses | B5: 30 | C5: 1829000 | D5: =C5/C$8 -> 0.013949134
A6: B - Activo con atraso largo (>24 meses) | B6: 18 | C6: 5794000 | D6: =C6/C$8 -> 0.044188782
A7: C - Inactivo o sin dato (cobro difícil) | B7: 379 | C7: 1.2349625e+08 | D7: =C7/C$8 -> 0.94186208
A8: Total | B8: =SUM(B5:B7) -> 427 | C8: =SUM(C5:C7) -> 1.3111925e+08 | D8: =SUM(D5:D7) -> 1

Sheet Calidad
A1: Calidad de los datos
A2: Problemas detectados y acción tomada.
A4: Problema | B4: Base | C4: Hallazgo | D4: Acción
A5: Filas duplicadas | B5: Morosos | C5: 2 pares idénticos en las 9 columnas; la base no tiene identificador | D5: Se eliminó una fila de cada par; confirmar en la fuente
A6: Institución: espacios y mayúsculas | B6: Morosos | C6: 9 categorías aparentes, en realidad 4 | D6: Unificadas en 4
A7: Condición y grado con espacios | B7: Padrón | C7: 215 celdas | D7: Espacios recortados
A8: Grado con mayúsculas inconsistentes | B8: Padrón | C8: 2 casos ('licenciatura') | D8: Unificado
A9: Valores faltantes | B9: Morosos | C9: 4 registros sin condición, grado ni fecha (sin coincidencia en la segunda base) | D9: Conservados para edad, sexo, institución y deuda; excluidos de los análisis de factores
A10: Emparejamiento dudoso | B10: Morosos | C10: 41 con sexo en conflicto y 88 con sexo no verificable | D10: No eliminados; sus datos cruzados pueden tener errores
A11: Atraso mayor que la antigüedad | B11: Morosos | C11: 20 registros con más meses de atraso que meses de colegiatura | D11: Sin cambios; revisar en la fuente
A12: Carné no coincide con la fecha | B12: Padrón | C12: 109 casos (47 con 1 año de diferencia; 50 con 23-24 años) | D12: No corregido; el carné no se usó
A13: Deuda = cuota fija × meses | B13: Morosos | C13: Cuota implícita de ₡5.861 por mes (rango ₡5.333 a ₡7.000) | D13: La deuda no aporta información independiente
